{
 "cells": [
  {
   "cell_type": "markdown",
   "id": "f30fed05-45f7-4176-be36-b79eb6445815",
   "metadata": {},
   "source": [
    "## Batch fitting\n",
    "This is the example ilustarting how fitting to multiple data sets can be acheived. This example has been developed during code CodeCampV in Grenoble, Apr 2017 by Miguel Gonzales and Marco Adamo.\n",
    "The script reads a series of files from GRASP and fits the model defined by model.py.\n",
    "For example ellipsoid.py fits a ellipsoid form factor model.\n",
    "For each file a directory named Fit_filename is created. The file model.par contains the fitted parameters, which are gathered together into batch_fit.csv in the current directory.\n",
    "Finally the fitted parameters are plotted for the full series."
   ]
  },
  {
   "cell_type": "code",
   "execution_count": 1,
   "id": "f47cf9a3-fb11-45f7-b8cc-29f78340e340",
   "metadata": {},
   "outputs": [],
   "source": [
    "import sys\n",
    "import os\n",
    "import numpy as np\n",
    "\n",
    "import matplotlib.pyplot as plt\n",
    "from bumps.dream.views import tile_axes  # make a grid of plots"
   ]
  },
  {
   "cell_type": "markdown",
   "id": "6e28189b-e94f-41f5-87ae-ee85b128d237",
   "metadata": {},
   "source": [
    "### Load data and set up parameters"
   ]
  },
  {
   "cell_type": "code",
   "execution_count": 5,
   "id": "265c1d9b-b0b8-4780-9829-f61e7639ace6",
   "metadata": {},
   "outputs": [],
   "source": [
    "path = 'notebook_files'\n",
    "model_file = f\"{path}/custom_ellipsoid.py\"\n",
    "data_files = [\"093191_201.dat\", \"093192_202.dat\",\"093193_203.dat\", \"093194_204.dat\", \"093195_205.dat\"]\n",
    "#ftol: f(x) tolerance uses differences in the function value to decide when the fit is complete\n",
    "#xtol: x tolerance uses differences in the parameter value to decide when the fit is complete\n",
    "fit_opts = \"--fit=lm --steps=200 --ftol=1.5e-8 --xtol=1.5e-8\"\n",
    "fit_opts = [v for v in fit_opts if v.startswith('--')]"
   ]
  },
  {
   "cell_type": "markdown",
   "id": "afc4192f-6d00-4390-8dfd-79df9470f1c4",
   "metadata": {},
   "source": [
    "### Check that data files exist"
   ]
  },
  {
   "cell_type": "code",
   "execution_count": 6,
   "id": "92cc1fc1-3f9d-4674-87fe-2de418666f60",
   "metadata": {},
   "outputs": [],
   "source": [
    "def fit_dir(filename):\n",
    "    \"Return the store directory name for the given file\"\n",
    "    return \"Fit_\" + os.path.splitext(filename)[0]"
   ]
  },
  {
   "cell_type": "markdown",
   "id": "ba1aacfd-08e6-4d30-9f53-950a435006ed",
   "metadata": {},
   "source": [
    "### Loop over files in bumps\n",
    "**Note:** Bumps is run from command line"
   ]
  },
  {
   "cell_type": "code",
   "execution_count": 7,
   "id": "f652cccf-c6be-4fa3-b315-1022cedb9ed8",
   "metadata": {},
   "outputs": [
    {
     "name": "stderr",
     "output_type": "stream",
     "text": [
      "WARNING:sas.sascalc.dataloader.file_reader_base_class:Unable to find file at: notebook_files/093191_201.dat\n",
      "Please check your file path and try again.\n",
      "Traceback (most recent call last):\n",
      "  File \"/Users/wojciechpotrzebowski/opt/anaconda3/envs/sasview_devt/lib/python3.9/site-packages/sasview-5.0.5-py3.9.egg/sas/sascalc/dataloader/loader.py\", line 74, in load\n",
      "    data_list = super(Registry, self).load(path, format=format)\n",
      "  File \"/Users/wojciechpotrzebowski/opt/anaconda3/envs/sasview_devt/lib/python3.9/site-packages/sasview-5.0.5-py3.9.egg/sas/sascalc/data_util/registry.py\", line 142, in load\n",
      "    raise last_exc\n",
      "  File \"/Users/wojciechpotrzebowski/opt/anaconda3/envs/sasview_devt/lib/python3.9/site-packages/sasview-5.0.5-py3.9.egg/sas/sascalc/data_util/registry.py\", line 137, in load\n",
      "    return fn(path)\n",
      "  File \"/Users/wojciechpotrzebowski/opt/anaconda3/envs/sasview_devt/lib/python3.9/site-packages/sasview-5.0.5-py3.9.egg/sas/sascalc/dataloader/file_reader_base_class.py\", line 118, in read\n",
      "    self.handle_error_message(msg)\n",
      "  File \"/Users/wojciechpotrzebowski/opt/anaconda3/envs/sasview_devt/lib/python3.9/site-packages/sasview-5.0.5-py3.9.egg/sas/sascalc/dataloader/file_reader_base_class.py\", line 169, in handle_error_message\n",
      "    raise NoKnownLoaderException(msg)\n",
      "sas.sascalc.dataloader.loader_exceptions.NoKnownLoaderException: Unable to find file at: notebook_files/093191_201.dat\n",
      "Please check your file path and try again.\n",
      "WARNING:sas.sascalc.dataloader.file_reader_base_class:Unable to find file at: notebook_files/093191_201.dat\n",
      "Please check your file path and try again.\n",
      "WARNING:sas.sascalc.dataloader.file_reader_base_class:Unable to find file at: notebook_files/093191_201.dat\n",
      "Please check your file path and try again.\n",
      "WARNING:sas.sascalc.dataloader.file_reader_base_class:Unable to find file at: notebook_files/093191_201.dat\n",
      "Please check your file path and try again.\n",
      "Traceback (most recent call last):\n",
      "  File \"/Users/wojciechpotrzebowski/opt/anaconda3/envs/sasview_devt/lib/python3.9/site-packages/sasview-5.0.5-py3.9.egg/sas/sascalc/dataloader/loader.py\", line 88, in load\n",
      "    return self.load_using_generic_loaders(path)\n",
      "  File \"/Users/wojciechpotrzebowski/opt/anaconda3/envs/sasview_devt/lib/python3.9/site-packages/sasview-5.0.5-py3.9.egg/sas/sascalc/dataloader/loader.py\", line 120, in load_using_generic_loaders\n",
      "    raise NoKnownLoaderException(\n",
      "sas.sascalc.dataloader.loader_exceptions.NoKnownLoaderException: Generic readers failed to load notebook_files/093191_201.dat\n",
      "ERROR:sas.sascalc.dataloader.loader:Generic readers failed to load notebook_files/093191_201.dat\n",
      "Unknown data format: notebook_files/093191_201.dat.\n",
      "The file is not a known format that can be loaded by SasView.\n",
      "\n",
      "Traceback (most recent call last):\n",
      "  File \"/Users/wojciechpotrzebowski/opt/anaconda3/envs/sasview_devt/lib/python3.9/runpy.py\", line 197, in _run_module_as_main\n",
      "    return _run_code(code, main_globals, None,\n",
      "  File \"/Users/wojciechpotrzebowski/opt/anaconda3/envs/sasview_devt/lib/python3.9/runpy.py\", line 87, in _run_code\n",
      "    exec(code, run_globals)\n",
      "  File \"/Users/wojciechpotrzebowski/opt/anaconda3/envs/sasview_devt/lib/python3.9/site-packages/bumps-0.9.0-py3.9.egg/bumps/cli.py\", line 730, in <module>\n",
      "    main()\n",
      "  File \"/Users/wojciechpotrzebowski/opt/anaconda3/envs/sasview_devt/lib/python3.9/site-packages/bumps-0.9.0-py3.9.egg/bumps/cli.py\", line 575, in main\n",
      "    problem = initial_model(opts)\n",
      "  File \"/Users/wojciechpotrzebowski/opt/anaconda3/envs/sasview_devt/lib/python3.9/site-packages/bumps-0.9.0-py3.9.egg/bumps/cli.py\", line 341, in initial_model\n",
      "    problem = load_model(opts.args[0], opts.args[1:])\n",
      "  File \"/Users/wojciechpotrzebowski/opt/anaconda3/envs/sasview_devt/lib/python3.9/site-packages/bumps-0.9.0-py3.9.egg/bumps/cli.py\", line 92, in load_model\n",
      "    problem = load_problem(filename, options=model_options)\n",
      "  File \"/Users/wojciechpotrzebowski/opt/anaconda3/envs/sasview_devt/lib/python3.9/site-packages/bumps-0.9.0-py3.9.egg/bumps/fitproblem.py\", line 793, in load_problem\n",
      "    exec(code, ctx)\n",
      "  File \"custom_ellipsoid.py\", line 12, in <module>\n",
      "  File \"/Users/wojciechpotrzebowski/opt/anaconda3/envs/sasview_devt/lib/python3.9/site-packages/sasmodels-1.0.5-py3.9.egg/sasmodels/data.py\", line 63, in load_data\n",
      "    datasets = loader.load(filename)\n",
      "  File \"/Users/wojciechpotrzebowski/opt/anaconda3/envs/sasview_devt/lib/python3.9/site-packages/sasview-5.0.5-py3.9.egg/sas/sascalc/dataloader/loader.py\", line 393, in load\n",
      "    return self.__registry.load(file, format)\n",
      "  File \"/Users/wojciechpotrzebowski/opt/anaconda3/envs/sasview_devt/lib/python3.9/site-packages/sasview-5.0.5-py3.9.egg/sas/sascalc/dataloader/loader.py\", line 88, in load\n",
      "    return self.load_using_generic_loaders(path)\n",
      "  File \"/Users/wojciechpotrzebowski/opt/anaconda3/envs/sasview_devt/lib/python3.9/site-packages/sasview-5.0.5-py3.9.egg/sas/sascalc/dataloader/loader.py\", line 120, in load_using_generic_loaders\n",
      "    raise NoKnownLoaderException(\n",
      "sas.sascalc.dataloader.loader_exceptions.NoKnownLoaderException: Generic readers failed to load notebook_files/093191_201.dat\n",
      "WARNING:sas.sascalc.dataloader.file_reader_base_class:Unable to find file at: notebook_files/093192_202.dat\n",
      "Please check your file path and try again.\n",
      "Traceback (most recent call last):\n",
      "  File \"/Users/wojciechpotrzebowski/opt/anaconda3/envs/sasview_devt/lib/python3.9/site-packages/sasview-5.0.5-py3.9.egg/sas/sascalc/dataloader/loader.py\", line 74, in load\n",
      "    data_list = super(Registry, self).load(path, format=format)\n",
      "  File \"/Users/wojciechpotrzebowski/opt/anaconda3/envs/sasview_devt/lib/python3.9/site-packages/sasview-5.0.5-py3.9.egg/sas/sascalc/data_util/registry.py\", line 142, in load\n",
      "    raise last_exc\n",
      "  File \"/Users/wojciechpotrzebowski/opt/anaconda3/envs/sasview_devt/lib/python3.9/site-packages/sasview-5.0.5-py3.9.egg/sas/sascalc/data_util/registry.py\", line 137, in load\n",
      "    return fn(path)\n",
      "  File \"/Users/wojciechpotrzebowski/opt/anaconda3/envs/sasview_devt/lib/python3.9/site-packages/sasview-5.0.5-py3.9.egg/sas/sascalc/dataloader/file_reader_base_class.py\", line 118, in read\n",
      "    self.handle_error_message(msg)\n",
      "  File \"/Users/wojciechpotrzebowski/opt/anaconda3/envs/sasview_devt/lib/python3.9/site-packages/sasview-5.0.5-py3.9.egg/sas/sascalc/dataloader/file_reader_base_class.py\", line 169, in handle_error_message\n",
      "    raise NoKnownLoaderException(msg)\n",
      "sas.sascalc.dataloader.loader_exceptions.NoKnownLoaderException: Unable to find file at: notebook_files/093192_202.dat\n",
      "Please check your file path and try again.\n",
      "WARNING:sas.sascalc.dataloader.file_reader_base_class:Unable to find file at: notebook_files/093192_202.dat\n",
      "Please check your file path and try again.\n",
      "WARNING:sas.sascalc.dataloader.file_reader_base_class:Unable to find file at: notebook_files/093192_202.dat\n",
      "Please check your file path and try again.\n",
      "WARNING:sas.sascalc.dataloader.file_reader_base_class:Unable to find file at: notebook_files/093192_202.dat\n",
      "Please check your file path and try again.\n",
      "Traceback (most recent call last):\n",
      "  File \"/Users/wojciechpotrzebowski/opt/anaconda3/envs/sasview_devt/lib/python3.9/site-packages/sasview-5.0.5-py3.9.egg/sas/sascalc/dataloader/loader.py\", line 88, in load\n",
      "    return self.load_using_generic_loaders(path)\n",
      "  File \"/Users/wojciechpotrzebowski/opt/anaconda3/envs/sasview_devt/lib/python3.9/site-packages/sasview-5.0.5-py3.9.egg/sas/sascalc/dataloader/loader.py\", line 120, in load_using_generic_loaders\n",
      "    raise NoKnownLoaderException(\n",
      "sas.sascalc.dataloader.loader_exceptions.NoKnownLoaderException: Generic readers failed to load notebook_files/093192_202.dat\n",
      "ERROR:sas.sascalc.dataloader.loader:Generic readers failed to load notebook_files/093192_202.dat\n",
      "Unknown data format: notebook_files/093192_202.dat.\n",
      "The file is not a known format that can be loaded by SasView.\n",
      "\n",
      "Traceback (most recent call last):\n",
      "  File \"/Users/wojciechpotrzebowski/opt/anaconda3/envs/sasview_devt/lib/python3.9/runpy.py\", line 197, in _run_module_as_main\n",
      "    return _run_code(code, main_globals, None,\n",
      "  File \"/Users/wojciechpotrzebowski/opt/anaconda3/envs/sasview_devt/lib/python3.9/runpy.py\", line 87, in _run_code\n",
      "    exec(code, run_globals)\n",
      "  File \"/Users/wojciechpotrzebowski/opt/anaconda3/envs/sasview_devt/lib/python3.9/site-packages/bumps-0.9.0-py3.9.egg/bumps/cli.py\", line 730, in <module>\n",
      "    main()\n",
      "  File \"/Users/wojciechpotrzebowski/opt/anaconda3/envs/sasview_devt/lib/python3.9/site-packages/bumps-0.9.0-py3.9.egg/bumps/cli.py\", line 575, in main\n",
      "    problem = initial_model(opts)\n",
      "  File \"/Users/wojciechpotrzebowski/opt/anaconda3/envs/sasview_devt/lib/python3.9/site-packages/bumps-0.9.0-py3.9.egg/bumps/cli.py\", line 341, in initial_model\n",
      "    problem = load_model(opts.args[0], opts.args[1:])\n",
      "  File \"/Users/wojciechpotrzebowski/opt/anaconda3/envs/sasview_devt/lib/python3.9/site-packages/bumps-0.9.0-py3.9.egg/bumps/cli.py\", line 92, in load_model\n",
      "    problem = load_problem(filename, options=model_options)\n",
      "  File \"/Users/wojciechpotrzebowski/opt/anaconda3/envs/sasview_devt/lib/python3.9/site-packages/bumps-0.9.0-py3.9.egg/bumps/fitproblem.py\", line 793, in load_problem\n",
      "    exec(code, ctx)\n",
      "  File \"custom_ellipsoid.py\", line 12, in <module>\n",
      "  File \"/Users/wojciechpotrzebowski/opt/anaconda3/envs/sasview_devt/lib/python3.9/site-packages/sasmodels-1.0.5-py3.9.egg/sasmodels/data.py\", line 63, in load_data\n",
      "    datasets = loader.load(filename)\n",
      "  File \"/Users/wojciechpotrzebowski/opt/anaconda3/envs/sasview_devt/lib/python3.9/site-packages/sasview-5.0.5-py3.9.egg/sas/sascalc/dataloader/loader.py\", line 393, in load\n",
      "    return self.__registry.load(file, format)\n",
      "  File \"/Users/wojciechpotrzebowski/opt/anaconda3/envs/sasview_devt/lib/python3.9/site-packages/sasview-5.0.5-py3.9.egg/sas/sascalc/dataloader/loader.py\", line 88, in load\n",
      "    return self.load_using_generic_loaders(path)\n",
      "  File \"/Users/wojciechpotrzebowski/opt/anaconda3/envs/sasview_devt/lib/python3.9/site-packages/sasview-5.0.5-py3.9.egg/sas/sascalc/dataloader/loader.py\", line 120, in load_using_generic_loaders\n",
      "    raise NoKnownLoaderException(\n",
      "sas.sascalc.dataloader.loader_exceptions.NoKnownLoaderException: Generic readers failed to load notebook_files/093192_202.dat\n",
      "WARNING:sas.sascalc.dataloader.file_reader_base_class:Unable to find file at: notebook_files/093193_203.dat\n",
      "Please check your file path and try again.\n",
      "Traceback (most recent call last):\n",
      "  File \"/Users/wojciechpotrzebowski/opt/anaconda3/envs/sasview_devt/lib/python3.9/site-packages/sasview-5.0.5-py3.9.egg/sas/sascalc/dataloader/loader.py\", line 74, in load\n",
      "    data_list = super(Registry, self).load(path, format=format)\n",
      "  File \"/Users/wojciechpotrzebowski/opt/anaconda3/envs/sasview_devt/lib/python3.9/site-packages/sasview-5.0.5-py3.9.egg/sas/sascalc/data_util/registry.py\", line 142, in load\n",
      "    raise last_exc\n",
      "  File \"/Users/wojciechpotrzebowski/opt/anaconda3/envs/sasview_devt/lib/python3.9/site-packages/sasview-5.0.5-py3.9.egg/sas/sascalc/data_util/registry.py\", line 137, in load\n",
      "    return fn(path)\n",
      "  File \"/Users/wojciechpotrzebowski/opt/anaconda3/envs/sasview_devt/lib/python3.9/site-packages/sasview-5.0.5-py3.9.egg/sas/sascalc/dataloader/file_reader_base_class.py\", line 118, in read\n",
      "    self.handle_error_message(msg)\n",
      "  File \"/Users/wojciechpotrzebowski/opt/anaconda3/envs/sasview_devt/lib/python3.9/site-packages/sasview-5.0.5-py3.9.egg/sas/sascalc/dataloader/file_reader_base_class.py\", line 169, in handle_error_message\n",
      "    raise NoKnownLoaderException(msg)\n",
      "sas.sascalc.dataloader.loader_exceptions.NoKnownLoaderException: Unable to find file at: notebook_files/093193_203.dat\n",
      "Please check your file path and try again.\n",
      "WARNING:sas.sascalc.dataloader.file_reader_base_class:Unable to find file at: notebook_files/093193_203.dat\n",
      "Please check your file path and try again.\n",
      "WARNING:sas.sascalc.dataloader.file_reader_base_class:Unable to find file at: notebook_files/093193_203.dat\n",
      "Please check your file path and try again.\n",
      "WARNING:sas.sascalc.dataloader.file_reader_base_class:Unable to find file at: notebook_files/093193_203.dat\n",
      "Please check your file path and try again.\n",
      "Traceback (most recent call last):\n",
      "  File \"/Users/wojciechpotrzebowski/opt/anaconda3/envs/sasview_devt/lib/python3.9/site-packages/sasview-5.0.5-py3.9.egg/sas/sascalc/dataloader/loader.py\", line 88, in load\n",
      "    return self.load_using_generic_loaders(path)\n",
      "  File \"/Users/wojciechpotrzebowski/opt/anaconda3/envs/sasview_devt/lib/python3.9/site-packages/sasview-5.0.5-py3.9.egg/sas/sascalc/dataloader/loader.py\", line 120, in load_using_generic_loaders\n",
      "    raise NoKnownLoaderException(\n",
      "sas.sascalc.dataloader.loader_exceptions.NoKnownLoaderException: Generic readers failed to load notebook_files/093193_203.dat\n",
      "ERROR:sas.sascalc.dataloader.loader:Generic readers failed to load notebook_files/093193_203.dat\n",
      "Unknown data format: notebook_files/093193_203.dat.\n",
      "The file is not a known format that can be loaded by SasView.\n",
      "\n",
      "Traceback (most recent call last):\n",
      "  File \"/Users/wojciechpotrzebowski/opt/anaconda3/envs/sasview_devt/lib/python3.9/runpy.py\", line 197, in _run_module_as_main\n",
      "    return _run_code(code, main_globals, None,\n",
      "  File \"/Users/wojciechpotrzebowski/opt/anaconda3/envs/sasview_devt/lib/python3.9/runpy.py\", line 87, in _run_code\n",
      "    exec(code, run_globals)\n",
      "  File \"/Users/wojciechpotrzebowski/opt/anaconda3/envs/sasview_devt/lib/python3.9/site-packages/bumps-0.9.0-py3.9.egg/bumps/cli.py\", line 730, in <module>\n",
      "    main()\n",
      "  File \"/Users/wojciechpotrzebowski/opt/anaconda3/envs/sasview_devt/lib/python3.9/site-packages/bumps-0.9.0-py3.9.egg/bumps/cli.py\", line 575, in main\n",
      "    problem = initial_model(opts)\n",
      "  File \"/Users/wojciechpotrzebowski/opt/anaconda3/envs/sasview_devt/lib/python3.9/site-packages/bumps-0.9.0-py3.9.egg/bumps/cli.py\", line 341, in initial_model\n",
      "    problem = load_model(opts.args[0], opts.args[1:])\n",
      "  File \"/Users/wojciechpotrzebowski/opt/anaconda3/envs/sasview_devt/lib/python3.9/site-packages/bumps-0.9.0-py3.9.egg/bumps/cli.py\", line 92, in load_model\n",
      "    problem = load_problem(filename, options=model_options)\n",
      "  File \"/Users/wojciechpotrzebowski/opt/anaconda3/envs/sasview_devt/lib/python3.9/site-packages/bumps-0.9.0-py3.9.egg/bumps/fitproblem.py\", line 793, in load_problem\n",
      "    exec(code, ctx)\n",
      "  File \"custom_ellipsoid.py\", line 12, in <module>\n",
      "  File \"/Users/wojciechpotrzebowski/opt/anaconda3/envs/sasview_devt/lib/python3.9/site-packages/sasmodels-1.0.5-py3.9.egg/sasmodels/data.py\", line 63, in load_data\n",
      "    datasets = loader.load(filename)\n",
      "  File \"/Users/wojciechpotrzebowski/opt/anaconda3/envs/sasview_devt/lib/python3.9/site-packages/sasview-5.0.5-py3.9.egg/sas/sascalc/dataloader/loader.py\", line 393, in load\n",
      "    return self.__registry.load(file, format)\n",
      "  File \"/Users/wojciechpotrzebowski/opt/anaconda3/envs/sasview_devt/lib/python3.9/site-packages/sasview-5.0.5-py3.9.egg/sas/sascalc/dataloader/loader.py\", line 88, in load\n",
      "    return self.load_using_generic_loaders(path)\n",
      "  File \"/Users/wojciechpotrzebowski/opt/anaconda3/envs/sasview_devt/lib/python3.9/site-packages/sasview-5.0.5-py3.9.egg/sas/sascalc/dataloader/loader.py\", line 120, in load_using_generic_loaders\n",
      "    raise NoKnownLoaderException(\n",
      "sas.sascalc.dataloader.loader_exceptions.NoKnownLoaderException: Generic readers failed to load notebook_files/093193_203.dat\n",
      "WARNING:sas.sascalc.dataloader.file_reader_base_class:Unable to find file at: notebook_files/093194_204.dat\n",
      "Please check your file path and try again.\n",
      "Traceback (most recent call last):\n",
      "  File \"/Users/wojciechpotrzebowski/opt/anaconda3/envs/sasview_devt/lib/python3.9/site-packages/sasview-5.0.5-py3.9.egg/sas/sascalc/dataloader/loader.py\", line 74, in load\n",
      "    data_list = super(Registry, self).load(path, format=format)\n",
      "  File \"/Users/wojciechpotrzebowski/opt/anaconda3/envs/sasview_devt/lib/python3.9/site-packages/sasview-5.0.5-py3.9.egg/sas/sascalc/data_util/registry.py\", line 142, in load\n",
      "    raise last_exc\n",
      "  File \"/Users/wojciechpotrzebowski/opt/anaconda3/envs/sasview_devt/lib/python3.9/site-packages/sasview-5.0.5-py3.9.egg/sas/sascalc/data_util/registry.py\", line 137, in load\n",
      "    return fn(path)\n",
      "  File \"/Users/wojciechpotrzebowski/opt/anaconda3/envs/sasview_devt/lib/python3.9/site-packages/sasview-5.0.5-py3.9.egg/sas/sascalc/dataloader/file_reader_base_class.py\", line 118, in read\n",
      "    self.handle_error_message(msg)\n",
      "  File \"/Users/wojciechpotrzebowski/opt/anaconda3/envs/sasview_devt/lib/python3.9/site-packages/sasview-5.0.5-py3.9.egg/sas/sascalc/dataloader/file_reader_base_class.py\", line 169, in handle_error_message\n",
      "    raise NoKnownLoaderException(msg)\n",
      "sas.sascalc.dataloader.loader_exceptions.NoKnownLoaderException: Unable to find file at: notebook_files/093194_204.dat\n",
      "Please check your file path and try again.\n",
      "WARNING:sas.sascalc.dataloader.file_reader_base_class:Unable to find file at: notebook_files/093194_204.dat\n",
      "Please check your file path and try again.\n",
      "WARNING:sas.sascalc.dataloader.file_reader_base_class:Unable to find file at: notebook_files/093194_204.dat\n",
      "Please check your file path and try again.\n",
      "WARNING:sas.sascalc.dataloader.file_reader_base_class:Unable to find file at: notebook_files/093194_204.dat\n",
      "Please check your file path and try again.\n",
      "Traceback (most recent call last):\n",
      "  File \"/Users/wojciechpotrzebowski/opt/anaconda3/envs/sasview_devt/lib/python3.9/site-packages/sasview-5.0.5-py3.9.egg/sas/sascalc/dataloader/loader.py\", line 88, in load\n",
      "    return self.load_using_generic_loaders(path)\n",
      "  File \"/Users/wojciechpotrzebowski/opt/anaconda3/envs/sasview_devt/lib/python3.9/site-packages/sasview-5.0.5-py3.9.egg/sas/sascalc/dataloader/loader.py\", line 120, in load_using_generic_loaders\n",
      "    raise NoKnownLoaderException(\n",
      "sas.sascalc.dataloader.loader_exceptions.NoKnownLoaderException: Generic readers failed to load notebook_files/093194_204.dat\n",
      "ERROR:sas.sascalc.dataloader.loader:Generic readers failed to load notebook_files/093194_204.dat\n",
      "Unknown data format: notebook_files/093194_204.dat.\n",
      "The file is not a known format that can be loaded by SasView.\n",
      "\n",
      "Traceback (most recent call last):\n",
      "  File \"/Users/wojciechpotrzebowski/opt/anaconda3/envs/sasview_devt/lib/python3.9/runpy.py\", line 197, in _run_module_as_main\n",
      "    return _run_code(code, main_globals, None,\n",
      "  File \"/Users/wojciechpotrzebowski/opt/anaconda3/envs/sasview_devt/lib/python3.9/runpy.py\", line 87, in _run_code\n",
      "    exec(code, run_globals)\n",
      "  File \"/Users/wojciechpotrzebowski/opt/anaconda3/envs/sasview_devt/lib/python3.9/site-packages/bumps-0.9.0-py3.9.egg/bumps/cli.py\", line 730, in <module>\n",
      "    main()\n",
      "  File \"/Users/wojciechpotrzebowski/opt/anaconda3/envs/sasview_devt/lib/python3.9/site-packages/bumps-0.9.0-py3.9.egg/bumps/cli.py\", line 575, in main\n",
      "    problem = initial_model(opts)\n",
      "  File \"/Users/wojciechpotrzebowski/opt/anaconda3/envs/sasview_devt/lib/python3.9/site-packages/bumps-0.9.0-py3.9.egg/bumps/cli.py\", line 341, in initial_model\n",
      "    problem = load_model(opts.args[0], opts.args[1:])\n",
      "  File \"/Users/wojciechpotrzebowski/opt/anaconda3/envs/sasview_devt/lib/python3.9/site-packages/bumps-0.9.0-py3.9.egg/bumps/cli.py\", line 92, in load_model\n",
      "    problem = load_problem(filename, options=model_options)\n",
      "  File \"/Users/wojciechpotrzebowski/opt/anaconda3/envs/sasview_devt/lib/python3.9/site-packages/bumps-0.9.0-py3.9.egg/bumps/fitproblem.py\", line 793, in load_problem\n",
      "    exec(code, ctx)\n",
      "  File \"custom_ellipsoid.py\", line 12, in <module>\n",
      "  File \"/Users/wojciechpotrzebowski/opt/anaconda3/envs/sasview_devt/lib/python3.9/site-packages/sasmodels-1.0.5-py3.9.egg/sasmodels/data.py\", line 63, in load_data\n",
      "    datasets = loader.load(filename)\n",
      "  File \"/Users/wojciechpotrzebowski/opt/anaconda3/envs/sasview_devt/lib/python3.9/site-packages/sasview-5.0.5-py3.9.egg/sas/sascalc/dataloader/loader.py\", line 393, in load\n",
      "    return self.__registry.load(file, format)\n",
      "  File \"/Users/wojciechpotrzebowski/opt/anaconda3/envs/sasview_devt/lib/python3.9/site-packages/sasview-5.0.5-py3.9.egg/sas/sascalc/dataloader/loader.py\", line 88, in load\n",
      "    return self.load_using_generic_loaders(path)\n",
      "  File \"/Users/wojciechpotrzebowski/opt/anaconda3/envs/sasview_devt/lib/python3.9/site-packages/sasview-5.0.5-py3.9.egg/sas/sascalc/dataloader/loader.py\", line 120, in load_using_generic_loaders\n",
      "    raise NoKnownLoaderException(\n",
      "sas.sascalc.dataloader.loader_exceptions.NoKnownLoaderException: Generic readers failed to load notebook_files/093194_204.dat\n",
      "WARNING:sas.sascalc.dataloader.file_reader_base_class:Unable to find file at: notebook_files/093195_205.dat\n",
      "Please check your file path and try again.\n",
      "Traceback (most recent call last):\n",
      "  File \"/Users/wojciechpotrzebowski/opt/anaconda3/envs/sasview_devt/lib/python3.9/site-packages/sasview-5.0.5-py3.9.egg/sas/sascalc/dataloader/loader.py\", line 74, in load\n",
      "    data_list = super(Registry, self).load(path, format=format)\n",
      "  File \"/Users/wojciechpotrzebowski/opt/anaconda3/envs/sasview_devt/lib/python3.9/site-packages/sasview-5.0.5-py3.9.egg/sas/sascalc/data_util/registry.py\", line 142, in load\n",
      "    raise last_exc\n",
      "  File \"/Users/wojciechpotrzebowski/opt/anaconda3/envs/sasview_devt/lib/python3.9/site-packages/sasview-5.0.5-py3.9.egg/sas/sascalc/data_util/registry.py\", line 137, in load\n",
      "    return fn(path)\n",
      "  File \"/Users/wojciechpotrzebowski/opt/anaconda3/envs/sasview_devt/lib/python3.9/site-packages/sasview-5.0.5-py3.9.egg/sas/sascalc/dataloader/file_reader_base_class.py\", line 118, in read\n",
      "    self.handle_error_message(msg)\n",
      "  File \"/Users/wojciechpotrzebowski/opt/anaconda3/envs/sasview_devt/lib/python3.9/site-packages/sasview-5.0.5-py3.9.egg/sas/sascalc/dataloader/file_reader_base_class.py\", line 169, in handle_error_message\n",
      "    raise NoKnownLoaderException(msg)\n",
      "sas.sascalc.dataloader.loader_exceptions.NoKnownLoaderException: Unable to find file at: notebook_files/093195_205.dat\n",
      "Please check your file path and try again.\n",
      "WARNING:sas.sascalc.dataloader.file_reader_base_class:Unable to find file at: notebook_files/093195_205.dat\n",
      "Please check your file path and try again.\n",
      "WARNING:sas.sascalc.dataloader.file_reader_base_class:Unable to find file at: notebook_files/093195_205.dat\n",
      "Please check your file path and try again.\n",
      "WARNING:sas.sascalc.dataloader.file_reader_base_class:Unable to find file at: notebook_files/093195_205.dat\n",
      "Please check your file path and try again.\n",
      "Traceback (most recent call last):\n",
      "  File \"/Users/wojciechpotrzebowski/opt/anaconda3/envs/sasview_devt/lib/python3.9/site-packages/sasview-5.0.5-py3.9.egg/sas/sascalc/dataloader/loader.py\", line 88, in load\n",
      "    return self.load_using_generic_loaders(path)\n",
      "  File \"/Users/wojciechpotrzebowski/opt/anaconda3/envs/sasview_devt/lib/python3.9/site-packages/sasview-5.0.5-py3.9.egg/sas/sascalc/dataloader/loader.py\", line 120, in load_using_generic_loaders\n",
      "    raise NoKnownLoaderException(\n",
      "sas.sascalc.dataloader.loader_exceptions.NoKnownLoaderException: Generic readers failed to load notebook_files/093195_205.dat\n",
      "ERROR:sas.sascalc.dataloader.loader:Generic readers failed to load notebook_files/093195_205.dat\n",
      "Unknown data format: notebook_files/093195_205.dat.\n",
      "The file is not a known format that can be loaded by SasView.\n",
      "\n",
      "Traceback (most recent call last):\n",
      "  File \"/Users/wojciechpotrzebowski/opt/anaconda3/envs/sasview_devt/lib/python3.9/runpy.py\", line 197, in _run_module_as_main\n",
      "    return _run_code(code, main_globals, None,\n",
      "  File \"/Users/wojciechpotrzebowski/opt/anaconda3/envs/sasview_devt/lib/python3.9/runpy.py\", line 87, in _run_code\n",
      "    exec(code, run_globals)\n",
      "  File \"/Users/wojciechpotrzebowski/opt/anaconda3/envs/sasview_devt/lib/python3.9/site-packages/bumps-0.9.0-py3.9.egg/bumps/cli.py\", line 730, in <module>\n",
      "    main()\n",
      "  File \"/Users/wojciechpotrzebowski/opt/anaconda3/envs/sasview_devt/lib/python3.9/site-packages/bumps-0.9.0-py3.9.egg/bumps/cli.py\", line 575, in main\n",
      "    problem = initial_model(opts)\n",
      "  File \"/Users/wojciechpotrzebowski/opt/anaconda3/envs/sasview_devt/lib/python3.9/site-packages/bumps-0.9.0-py3.9.egg/bumps/cli.py\", line 341, in initial_model\n",
      "    problem = load_model(opts.args[0], opts.args[1:])\n",
      "  File \"/Users/wojciechpotrzebowski/opt/anaconda3/envs/sasview_devt/lib/python3.9/site-packages/bumps-0.9.0-py3.9.egg/bumps/cli.py\", line 92, in load_model\n",
      "    problem = load_problem(filename, options=model_options)\n",
      "  File \"/Users/wojciechpotrzebowski/opt/anaconda3/envs/sasview_devt/lib/python3.9/site-packages/bumps-0.9.0-py3.9.egg/bumps/fitproblem.py\", line 793, in load_problem\n",
      "    exec(code, ctx)\n",
      "  File \"custom_ellipsoid.py\", line 12, in <module>\n",
      "  File \"/Users/wojciechpotrzebowski/opt/anaconda3/envs/sasview_devt/lib/python3.9/site-packages/sasmodels-1.0.5-py3.9.egg/sasmodels/data.py\", line 63, in load_data\n",
      "    datasets = loader.load(filename)\n",
      "  File \"/Users/wojciechpotrzebowski/opt/anaconda3/envs/sasview_devt/lib/python3.9/site-packages/sasview-5.0.5-py3.9.egg/sas/sascalc/dataloader/loader.py\", line 393, in load\n",
      "    return self.__registry.load(file, format)\n",
      "  File \"/Users/wojciechpotrzebowski/opt/anaconda3/envs/sasview_devt/lib/python3.9/site-packages/sasview-5.0.5-py3.9.egg/sas/sascalc/dataloader/loader.py\", line 88, in load\n",
      "    return self.load_using_generic_loaders(path)\n",
      "  File \"/Users/wojciechpotrzebowski/opt/anaconda3/envs/sasview_devt/lib/python3.9/site-packages/sasview-5.0.5-py3.9.egg/sas/sascalc/dataloader/loader.py\", line 120, in load_using_generic_loaders\n",
      "    raise NoKnownLoaderException(\n",
      "sas.sascalc.dataloader.loader_exceptions.NoKnownLoaderException: Generic readers failed to load notebook_files/093195_205.dat\n"
     ]
    }
   ],
   "source": [
    "bumps_cmd = \"python -m bumps.cli --batch\"\n",
    "fit_opts = \" \".join(fit_opts)\n",
    "for data_file in data_files:\n",
    "    data_file = f\"{path}/{data_file}\"\n",
    "    store_opts = \"--store=\" + fit_dir(data_file)\n",
    "    cmd = \" \".join((bumps_cmd, fit_opts, store_opts, model_file, data_file))\n",
    "    os.system(cmd)"
   ]
  },
  {
   "cell_type": "markdown",
   "id": "473d357d-239f-4642-a2d3-4561a0fc82ed",
   "metadata": {},
   "source": [
    "### Gather results"
   ]
  },
  {
   "cell_type": "code",
   "execution_count": null,
   "id": "81fffa1d-4f17-4f96-bf8d-679cd84b96a1",
   "metadata": {},
   "outputs": [],
   "source": [
    "results = {}\n",
    "par_file = os.path.splitext(model_file)[0] + '.par'\n",
    "for data_file in data_files:\n",
    "    with open(os.path.join(fit_dir(data_file), par_file), 'r') as fid:\n",
    "        for line in fid:\n",
    "            parameter, value = line.split()\n",
    "            results.setdefault(parameter, []).append(float(value))"
   ]
  },
  {
   "cell_type": "markdown",
   "id": "d44b06bb-5e70-469e-820c-60b6d3c1bbed",
   "metadata": {},
   "source": [
    "### Save results into file"
   ]
  },
  {
   "cell_type": "code",
   "execution_count": null,
   "id": "e4154859-15c4-4367-bf0d-9dbbababe2d5",
   "metadata": {},
   "outputs": [],
   "source": [
    "with open('batch_fit.csv', 'w') as fid:\n",
    "    parameters = list(sorted(results.keys()))\n",
    "    values_by_file = zip(*(v for k, v in sorted(results.items())))\n",
    "    fid.write(','.join(['filename'] + parameters) + '\\n')\n",
    "    for filename, values in zip(data_files, values_by_file):\n",
    "        fid.write(','.join([filename] + [str(v) for v in values]) + '\\n')"
   ]
  },
  {
   "cell_type": "markdown",
   "id": "5b2eb8a1-41bb-47c5-b096-c9ab3ec81c67",
   "metadata": {},
   "source": [
    "### Show fitted parameters"
   ]
  },
  {
   "cell_type": "code",
   "execution_count": null,
   "id": "07573b2b-b16f-4d5d-9c0b-dad7bab62c89",
   "metadata": {},
   "outputs": [],
   "source": [
    "nh, nw = tile_axes(len(results))\n",
    "ticks = np.arange(1, len(data_files)+1)\n",
    "labels = [os.path.splitext(filename)[0] for filename in data_files]\n",
    "for k, (parameter, values) in enumerate(sorted(results.items())):\n",
    "    plt.subplot(nh, nw, k+1)\n",
    "    plt.plot(ticks, values)\n",
    "    plt.xlim(ticks[0]-0.5, ticks[-1]+0.5)\n",
    "    if k%nh == nh-1:\n",
    "        plt.xticks(ticks, labels, rotation=30)\n",
    "    else:\n",
    "        plt.xticks(ticks, [' ']*len(labels))\n",
    "    plt.ylabel(parameter)\n",
    "plt.suptitle(\"Fits\")\n",
    "plt.show()"
   ]
  },
  {
   "cell_type": "code",
   "execution_count": null,
   "id": "d7210f47-838d-4292-af16-dafc342d9c98",
   "metadata": {},
   "outputs": [],
   "source": []
  }
 ],
 "metadata": {
  "kernelspec": {
   "display_name": "Python 3 (ipykernel)",
   "language": "python",
   "name": "python3"
  },
  "language_info": {
   "codemirror_mode": {
    "name": "ipython",
    "version": 3
   },
   "file_extension": ".py",
   "mimetype": "text/x-python",
   "name": "python",
   "nbconvert_exporter": "python",
   "pygments_lexer": "ipython3",
   "version": "3.9.12"
  }
 },
 "nbformat": 4,
 "nbformat_minor": 5
}
